Workbook

Sheet Summary
A1: Odyn GPUs (A100 / H100) vs Together AI: inference and fine-tuning
A3: The answer in 6 lines
A4: Inference price: our GPUs serve all four models for $0.27 to $0.50 per million output tokens. Together's 4B endpoint (1x H100, $5.49/hr) costs $0.99 at the same load and $0.42 at its best throughput, i.e. 1.3x to 3.2x ours.
A5: Inference speed: at 6 requests/s our best GPU is level with Together on 4B and 9B and ahead on 27B and gpt-oss; at 1 request/s Together is 5 to 7% ahead on 4B and 9B and 2x ahead on 27B, while our best result on gpt-oss is about 21% faster (0.54 s vs 0.69 s). Percentages are relative to Together's time. The first token arrives 2 to 6x sooner (29 to 109 ms vs 157 to 277 ms) and the slowest 1% of requests are steadier (9B p99 1.7 s vs 6.9 s).
A6: Fine-tune, time to a trained model: for 4B and 9B we hand back a trained model 2 to 14x sooner end to end (27B: 1.5x sooner up to 5k rows) (e.g. 9B on 5k rows: 6.6 min on H100 vs 16.8 min on Together incl. queue). Together is sooner only for 27B on 10k rows (41 vs 55 min).
A7: Fine-tune, raw training speed: Together's training phase is 2 to 5x faster than one of our GPUs on 5k/10k jobs (27B 10k: 10.9 vs 54.4 min). We should not claim to train faster.
A8: Fine-tune price: our GPUs train each job for $0.034 to $1.76 (GPU-hour cost); Together charges $4.00 per job for every model and size, 2.3x to 118x more.
A9: Not claimable yet: higher peak serving throughput (our high-concurrency tests froze from a client-side limit), the largest model at light load (Together 27B 2.1 s vs our 4.4 s), and fine-tune quality (not measured).
A11: What we tested
A12: Inference: Qwen3.5 4B / 9B / 27B and openai gpt-oss-20b served with vLLM on one A100 SXM4 80GB or one H100 PCIe 80GB, against Together AI dedicated endpoints. ShareGPT 1k / 5k / 10k (English, prompt + output <= 512 tokens), up to 128 output tokens, temperature 0, identical client code. Latency at 1, 2, 4, 6 requests/s; capacity at 16, 32, 64 concurrent. Fine-tuning: Qwen3.5 4B / 9B / 27B, LoRA r16 / alpha 32 / all linear layers, lr 1e-4, 1 epoch, effective batch 8, packed 4096-token sequences, ShareGPT 1k / 5k / 10k, identical settings on A100, H100 and Together's fine-tuning API.
A14: 1. Serving price per million output tokens
A15: Model | B15: A100 ($/M tokens) | C15: H100 ($/M tokens) | D15: Together ($/M tokens) | E15: Basis
A16: Qwen3.5-4B | B16: 0.32 | C16: 0.31 | D16: 0.99 (best 0.42) | E16: Clean throughput at 16 concurrent
A17: Qwen3.5-9B | B17: 0.42 | C17: 0.46 | D17: Price not confirmed | E17: Clean throughput at 16 concurrent
A18: Qwen3.5-27B | B18: 0.5 | C18: 0.47 | D18: Price not confirmed | E18: Clean throughput at 64 concurrent
A19: gpt-oss-20B | B19: 0.27 | C19: 0.31 | D19: Price not confirmed | E19: Clean throughput at 16 concurrent
A21: 2. Response time (average of valid runs across 1k / 5k / 10k)
A22: Model | B22: Metric | C22: A100 | D22: H100 | E22: Together | F22: A100 vs Together | G22: H100 vs Together
A23: Qwen3.5-4B | B23: First token (ms), 1 req/s | C23: 29 | D23: 58 | E23: 157 | F23: 81% faster | G23: 63% faster
A24: Qwen3.5-4B | B24: Median response (s), 1 req/s | C24: 0.92 | D24: 0.83 | E24: 0.79 | F24: 16% slower | G24: Within 5%
A25: Qwen3.5-4B | B25: Median response (s), 6 req/s | C25: 1.12 | D25: 1 | E25: 1.01 | F25: 11% slower | G25: Within 5%
A26: Qwen3.5-4B | B26: Slowest 1% (s), 6 req/s | C26: 1.14 | D26: 1.04 | E26: 1.16 | F26: Within 5% | G26: 10% faster
A27: Qwen3.5-4B | B27: Time per token (ms), 6 req/s | C27: 8.5 | D27: 7.5 | E27: 6.6 | F27: 28% slower | G27: 14% slower
A28: Qwen3.5-9B | B28: First token (ms), 1 req/s | C28: 41 | D28: 60 | E28: 253 | F28: 84% faster | G28: 76% faster
A29: Qwen3.5-9B | B29: Median response (s), 1 req/s | C29: 1.48 | D29: 1.39 | E29: 1.3 | F29: 14% slower | G29: 7% slower
A30: Qwen3.5-9B | B30: Median response (s), 6 req/s | C30: 1.65 | D30: 1.72 | E30: 1.64 | F30: Within 5% | G30: Within 5%
A31: Qwen3.5-9B | B31: Slowest 1% (s), 6 req/s | C31: 1.74 | D31: 1.74 | E31: 6.85 | F31: 75% faster | G31: 75% faster
A32: Qwen3.5-9B | B32: Time per token (ms), 6 req/s | C32: 12.7 | D32: 12.9 | E32: 10.8 | F32: 18% slower | G32: 20% slower
A33: Qwen3.5-27B | B33: First token (ms), 1 req/s | C33: 109 | D33: 102 | E33: 277 | F33: 61% faster | G33: 63% faster
A34: Qwen3.5-27B | B34: Median response (s), 1 req/s | C34: 4.7 | D34: 4.35 | E34: 2.08 | F34: 126% slower | G34: 109% slower
... A42: gpt-oss-20B | B42: Time per token (ms), 6 req/s | C42: 4.7 | D42: 5.7 | E42: 5 | F42: 7% faster | G42: 13% slower
A44: 3. Fine-tuning: time from submitting the job to a trained model (min)
A45: Model | B45: Rows | C45: A100 total (min) | D45: H100 total (min) | E45: Together total (min) | F45: Sooner
A46: Qwen3.5-4B | B46: 1k | C46: 1.2 | D46: 1.4 | E46: 16.1 | F46: Ours
A47: Qwen3.5-4B | B47: 5k | C47: 7.1 | D47: 4.7 | E47: 12.7 | F47: Ours
A48: Qwen3.5-4B | B48: 10k | C48: 10.9 | D48: 9.4 | E48: 19.3 | F48: Ours
A49: Qwen3.5-9B | B49: 1k | C49: 1.6 | D49: 1.3 | E49: 18.5 | F49: Ours
A50: Qwen3.5-9B | B50: 5k | C50: 7.5 | D50: 6.6 | E50: 16.8 | F50: Ours
A51: Qwen3.5-9B | B51: 10k | C51: 15 | D51: 13.3 | E51: 27.7 | F51: Ours
A52: Qwen3.5-27B | B52: 1k | C52: 6.1 | D52: 6.8 | E52: 23.9 | F52: Ours
...

Sheet Inference data
A1: Model | B1: Metric | C1: A100 SXM4 | D1: H100 PCIe | E1: Together | F1: Valid runs (A100/H100/Together)
A2: 4B | B2: p50 latency @ 1 req/s (s) | C2: 0.916 | D2: 0.826 | E2: 0.788 | F2: 3 / 3 / 2
A3: 4B | B3: p50 latency @ 6 req/s (s) | C3: 1.12 | D3: 1.003 | E3: 1.006 | F3: 3 / 3 / 3
A4: 4B | B4: p99 latency @ 6 req/s (s) | C4: 1.142 | D4: 1.045 | E4: 1.163 | F4: 3 / 3 / 3
A5: 4B | B5: TTFT p50 @ 1 req/s (ms) | C5: 29.329 | D5: 58.234 | E5: 156.614 | F5: 3 / 3 / 2
A6: 4B | B6: Time per token @ 1 req/s (ms) | C6: 6.982 | D6: 6.041 | E6: 5.039 | F6: 3 / 3 / 2
A7: 4B | B7: Time per token @ 6 req/s (ms) | C7: 8.492 | D7: 7.525 | E7: 6.611 | F7: 3 / 3 / 3
A8: 4B | B8: Throughput @ 16 concurrent (tok/s) | C8: 1506.809 | D8: 1702.394 | E8: 1533.4 | F8: 2 / 1 / 3
A9: 4B | B9: Throughput @ 32 concurrent (tok/s) | E9: 2400.759 | F9: 0 / 0 / 3
A10: 4B | B10: Throughput @ 64 concurrent (tok/s) | E10: 3620.166 | F10: 0 / 0 / 3
A11: 9B | B11: p50 latency @ 1 req/s (s) | C11: 1.48 | D11: 1.39 | E11: 1.296 | F11: 3 / 3 / 3
A12: 9B | B12: p50 latency @ 6 req/s (s) | C12: 1.652 | D12: 1.722 | E12: 1.643 | F12: 3 / 3 / 3
A13: 9B | B13: p99 latency @ 6 req/s (s) | C13: 1.742 | D13: 1.735 | E13: 6.854 | F13: 3 / 3 / 3
A14: 9B | B14: TTFT p50 @ 1 req/s (ms) | C14: 40.594 | D14: 59.839 | E14: 252.897 | F14: 3 / 3 / 3
A15: 9B | B15: Time per token @ 1 req/s (ms) | C15: 11.346 | D15: 10.438 | E15: 8.439 | F15: 3 / 3 / 3
A16: 9B | B16: Time per token @ 6 req/s (ms) | C16: 12.714 | D16: 12.914 | E16: 10.79 | F16: 3 / 3 / 3
A17: 9B | B17: Throughput @ 16 concurrent (tok/s) | C17: 1137.232 | D17: 1170.604 | E17: 1104.579 | F17: 3 / 3 / 3
A18: 9B | B18: Throughput @ 32 concurrent (tok/s) | E18: 1752.317 | F18: 0 / 0 / 3
A19: 9B | B19: Throughput @ 64 concurrent (tok/s) | E19: 2749.479 | F19: 0 / 0 / 3
A20: 27B | B20: p50 latency @ 1 req/s (s) | C20: 4.702 | D20: 4.354 | E20: 2.084 | F20: 3 / 1 / 1
A21: 27B | B21: p50 latency @ 6 req/s (s) | C21: 7.119 | D21: 5.517 | E21: 8.175 | F21: 3 / 1 / 1
A22: 27B | B22: p99 latency @ 6 req/s (s) | C22: 7.58 | D22: 5.826 | E22: 11.31 | F22: 3 / 1 / 1
A23: 27B | B23: TTFT p50 @ 1 req/s (ms) | C23: 109.367 | D23: 101.65 | E23: 277.488 | F23: 3 / 1 / 1
A24: 27B | B24: Time per token @ 1 req/s (ms) | C24: 36.233 | D24: 33.58 | E24: 14.785 | F24: 3 / 1 / 1
A25: 27B | B25: Time per token @ 6 req/s (ms) | C25: 54.986 | D25: 42.762 | E25: 62.817 | F25: 3 / 1 / 1
A26: 27B | B26: Throughput @ 16 concurrent (tok/s) | C26: 378.058 | D26: 416.549 | E26: 596.4 | F26: 3 / 1 / 1
A27: 27B | B27: Throughput @ 32 concurrent (tok/s) | C27: 628.29 | D27: 725.432 | E27: 920.806 | F27: 3 / 1 / 1
A28: 27B | B28: Throughput @ 64 concurrent (tok/s) | C28: 955.492 | D28: 1131.698 | E28: 1369.677 | F28: 3 / 1 / 1
A29: gpt-oss-20B | B29: p50 latency @ 1 req/s (s) | C29: 0.55 | D29: 0.544 | E29: 0.691 | F29: 3 / 3 / 3
A30: gpt-oss-20B | B30: p50 latency @ 6 req/s (s) | C30: 0.81 | D30: 1.011 | E30: 0.868 | F30: 3 / 3 / 3
A31: gpt-oss-20B | B31: p99 latency @ 6 req/s (s) | C31: 0.989 | D31: 1.062 | E31: 1.151 | F31: 3 / 3 / 3
... A35: gpt-oss-20B | B35: Throughput @ 16 concurrent (tok/s) | C35: 1747.186 | D35: 1716.174 | E35: 1492.888 | F35: 1 / 1 / 3
A36: gpt-oss-20B | B36: Throughput @ 32 concurrent (tok/s) | E36: 2019.33 | F36: 0 / 0 / 3
A37: gpt-oss-20B | B37: Throughput @ 64 concurrent (tok/s) | F37: 0 / 0 / 0

Sheet Fine-tune data
A1: platform | B1: gpu | C1: model | D1: dataset_size | E1: lora | F1: effective_batch | G1: micro_batch | H1: grad_checkpointing | I1: trainable_params | J1: steps | K1: trained_tokens | L1: train_time_min | M1: queue_time_min | N1: total_time_min | O1: tokens_per_s | P1: steady_tokens_per_s | Q1: peak_memory_gb | R1: first_loss | S1: last_loss | T1: flash_linear_attention | U1: status | V1: notes
A2: A100 | B2: NVIDIA A100-SXM4-80GB | C2: Qwen3.5-4B | D2: 1k | E2: r16/a32/all-linear | F2: 8 | G2: 1 | H2: FALSE | I2: 32464896 | J2: 8 | K2: 262144 | L2: 0.996 | N2: 1.189 | O2: 4386.98 | P2: 4458.27 | Q2: 59.481 | R2: 1.224 | S2: 1.125 | T2: TRUE | U2: Valid
A3: A100 | B3: NVIDIA A100-SXM4-80GB | C3: Qwen3.5-4B | D3: 5k | E3: r16/a32/all-linear | F3: 8 | G3: 1 | H3: FALSE | I3: 32464896 | J3: 43 | K3: 1409024 | L3: 5.284 | N3: 7.101 | O3: 4444.11 | P3: 4456.26 | Q3: 59.582 | R3: 1.224 | S3: 1.101 | T3: TRUE | U3: Valid
A4: A100 | B4: NVIDIA A100-SXM4-80GB | C4: Qwen3.5-4B | D4: 10k | E4: r16/a32/all-linear | F4: 8 | G4: 1 | H4: FALSE | I4: 32464896 | J4: 87 | K4: 2850816 | L4: 10.68 | N4: 10.885 | O4: 4448.72 | P4: 4455.63 | Q4: 59.481 | R4: 1.224 | S4: 1.057 | T4: TRUE | U4: Valid
A5: A100 | B5: NVIDIA A100-SXM4-80GB | C5: Qwen3.5-9B | D5: 1k | E5: r16/a32/all-linear | F5: 8 | G5: 1 | H5: FALSE | I5: 43278336 | J5: 8 | K5: 262144 | L5: 1.377 | N5: 1.592 | O5: 3172.03 | P5: 3214.78 | Q5: 79.418 | R5: 1.181 | S5: 1.054 | T5: TRUE | U5: Valid | V5: Peak memory very close to the 80GB limit without checkpointing
A6: A100 | B6: NVIDIA A100-SXM4-80GB | C6: Qwen3.5-9B | D6: 5k | E6: r16/a32/all-linear | F6: 8 | G6: 1 | H6: FALSE | I6: 43278336 | J6: 43 | K6: 1409024 | L6: 7.331 | N6: 7.513 | O6: 3203.29 | P6: 3210.72 | Q6: 79.418 | R6: 1.181 | S6: 1.029 | T6: TRUE | U6: Valid | V6: Peak memory very close to the 80GB limit without checkpointing
A7: A100 | B7: NVIDIA A100-SXM4-80GB | C7: Qwen3.5-9B | D7: 10k | E7: r16/a32/all-linear | F7: 8 | G7: 1 | H7: FALSE | I7: 43278336 | J7: 87 | K7: 2850816 | L7: 14.805 | N7: 15.028 | O7: 3209.35 | P7: 3213.38 | Q7: 79.418 | R7: 1.181 | S7: 0.985 | T7: TRUE | U7: Valid | V7: Peak memory very close to the 80GB limit without checkpointing
A8: A100 | B8: NVIDIA A100-SXM4-80GB | C8: Qwen3.5-27B | D8: 1k | E8: r16/a32/all-linear | F8: 8 | G8: 1 | H8: TRUE | I8: 116727808 | J8: 8 | K8: 262144 | L8: 5.398 | N8: 6.054 | O8: 809.37 | P8: 809.44 | Q8: 70.652 | R8: 1.137 | S8: 0.975 | T8: TRUE | U8: Valid | V8: Gradient checkpointing required to fit on one 80GB GPU
A9: A100 | B9: NVIDIA A100-SXM4-80GB | C9: Qwen3.5-27B | D9: 5k | E9: r16/a32/all-linear | F9: 8 | G9: 1 | H9: TRUE | I9: 116727808 | J9: 43 | K9: 1409024 | L9: 29.008 | N9: 30.216 | O9: 809.55 | P9: 809.82 | Q9: 70.652 | R9: 1.137 | S9: 0.957 | T9: TRUE | U9: Valid | V9: Gradient checkpointing required to fit on one 80GB GPU
A10: A100 | B10: NVIDIA A100-SXM4-80GB | C10: Qwen3.5-27B | D10: 10k | E10: r16/a32/all-linear | F10: 8 | G10: 1 | H10: TRUE | I10: 116727808 | J10: 87 | K10: 2850816 | L10: 58.695 | N10: 59.356 | O10: 809.5 | P10: 809.74 | Q10: 70.652 | R10: 1.137 | S10: 0.909 | T10: TRUE | U10: Valid | V10: Gradient checkpointing required to fit on one 80GB GPU
A11: H100 | B11: NVIDIA H100 PCIe | C11: Qwen3.5-4B | D11: 1k | E11: r16/a32/all-linear | F11: 8 | G11: 1 | H11: FALSE | I11: 32464896 | J11: 8 | K11: 262144 | L11: 0.757 | N11: 1.373 | O11: 5774.21 | P11: 5804.29 | Q11: 59.531 | R11: 1.224 | S11: 1.126 | T11: TRUE | U11: Valid
A12: H100 | B12: NVIDIA H100 PCIe | C12: Qwen3.5-4B | D12: 5k | E12: r16/a32/all-linear | F12: 8 | G12: 1 | H12: FALSE | I12: 32464896 | J12: 43 | K12: 1409024 | L12: 4.567 | N12: 4.663 | O12: 5141.89 | P12: 5127.09 | Q12: 59.531 | R12: 1.224 | S12: 1.101 | T12: TRUE | U12: Valid | V12: ~11% slower steady-state than the 1k run on the same GPU/model — see Notes
A13: H100 | B13: NVIDIA H100 PCIe | C13: Qwen3.5-4B | D13: 10k | E13: r16/a32/all-linear | F13: 8 | G13: 1 | H13: FALSE | I13: 32464896 | J13: 87 | K13: 2850816 | L13: 9.259 | N13: 9.355 | O13: 5131.83 | P13: 5121.91 | Q13: 59.531 | R13: 1.224 | S13: 1.058 | T13: TRUE | U13: Valid | V13: ~11% slower steady-state than the 1k run on the same GPU/model — see Notes
A14: H100 | B14: NVIDIA H100 PCIe | C14: Qwen3.5-9B | D14: 1k | E14: r16/a32/all-linear | F14: 8 | G14: 1 | H14: FALSE | I14: 43278336 | J14: 8 | K14: 262144 | L14: 1.143 | N14: 1.258 | O14: 3820.94 | P14: 3739.78 | Q14: 79.469 | R14: 1.181 | S14: 1.054 | T14: TRUE | U14: Valid | V14: Peak memory very close to the 80GB limit without checkpointing
A15: H100 | B15: NVIDIA H100 PCIe | C15: Qwen3.5-9B | D15: 5k | E15: r16/a32/all-linear | F15: 8 | G15: 1 | H15: FALSE | I15: 43278336 | J15: 43 | K15: 1409024 | L15: 6.497 | N15: 6.613 | O15: 3614.7 | P15: 3603.26 | Q15: 79.469 | R15: 1.181 | S15: 1.03 | T15: TRUE | U15: Valid | V15: Peak memory very close to the 80GB limit without checkpointing
A16: H100 | B16: NVIDIA H100 PCIe | C16: Qwen3.5-9B | D16: 10k | E16: r16/a32/all-linear | F16: 8 | G16: 1 | H16: FALSE | I16: 43278336 | J16: 87 | K16: 2850816 | L16: 13.167 | N16: 13.284 | O16: 3608.41 | P16: 3603.12 | Q16: 79.469 | R16: 1.181 | S16: 0.984 | T16: TRUE | U16: Valid | V16: Peak memory very close to the 80GB limit without checkpointing
A17: H100 | B17: NVIDIA H100 PCIe | C17: Qwen3.5-27B | D17: 1k | E17: r16/a32/all-linear | F17: 8 | G17: 1 | H17: TRUE | I17: 116727808 | J17: 8 | K17: 262144 | L17: 4.832 | N17: 6.783 | O17: 904.27 | P17: 875.06 | Q17: 70.702 | R17: 1.137 | S17: 0.973 | T17: TRUE | U17: Valid | V17: First successful H100 27B run — earlier attempts crashed with a CUDA driver error unrelated to this methodology
A18: H100 | B18: NVIDIA H100 PCIe | C18: Qwen3.5-27B | D18: 5k | E18: r16/a32/all-linear | F18: 8 | G18: 1 | H18: TRUE | I18: 116727808 | J18: 43 | K18: 1409024 | L18: 26.862 | N18: 27.39 | O18: 874.23 | P18: 873.31 | Q18: 70.702 | R18: 1.137 | S18: 0.956 | T18: TRUE | U18: Valid | V18: First successful H100 27B run — earlier attempts crashed with a CUDA driver error unrelated to this methodology
A19: H100 | B19: NVIDIA H100 PCIe | C19: Qwen3.5-27B | D19: 10k | E19: r16/a32/all-linear | F19: 8 | G19: 1 | H19: TRUE | I19: 116727808 | J19: 87 | K19: 2850816 | L19: 54.413 | N19: 54.937 | O19: 873.21 | P19: 872.39 | Q19: 70.702 | R19: 1.137 | S19: 0.909 | T19: TRUE | U19: Valid | V19: First successful H100 27B run — earlier attempts crashed with a CUDA driver error unrelated to this methodology
A20: Together | B20: not disclosed | C20: Qwen3.5-4B | D20: 1k | E20: r16/a32/all-linear | F20: 8 | G20: 8 | H20: not disclosed | J20: 21 | K20: 287860 | L20: 4.9 | M20: 5.034 | N20: 16.051 | O20: 979.12 | U20: Caution | V20: Train time looks distorted by a fixed per-job overhead — slower than the larger 5k/10k jobs despite fewer steps
A21: Together | B21: not disclosed | C21: Qwen3.5-4B | D21: 5k | E21: r16/a32/all-linear | F21: 8 | G21: 8 | H21: not disclosed | J21: 44 | K21: 1435064 | L21: 2.617 | M21: 5.394 | N21: 12.71 | O21: 9140.54 | U21: Valid
A22: Together | B22: not disclosed | C22: Qwen3.5-4B | D22: 10k | E22: r16/a32/all-linear | F22: 8 | G22: 8 | H22: not disclosed | J22: 88 | K22: 2854762 | L22: 3.1 | M22: 5.326 | N22: 19.259 | O22: 15348.18 | U22: Valid
A23: Together | B23: not disclosed | C23: Qwen3.5-9B | D23: 1k | E23: r16/a32/all-linear | F23: 8 | G23: 8 | H23: not disclosed | J23: 21 | K23: 287860 | L23: 5.067 | M23: 5.216 | N23: 18.466 | O23: 946.91 | U23: Caution | V23: Train time looks distorted by a fixed per-job overhead — slower than the larger 5k/10k jobs despite fewer steps
A24: Together | B24: not disclosed | C24: Qwen3.5-9B | D24: 5k | E24: r16/a32/all-linear | F24: 8 | G24: 8 | H24: not disclosed | J24: 44 | K24: 1435064 | L24: 2.983 | M24: 5.85 | N24: 16.833 | O24: 8017.12 | U24: Valid
A25: Together | B25: not disclosed | C25: Qwen3.5-9B | D25: 10k | E25: r16/a32/all-linear | F25: 8 | G25: 8 | H25: not disclosed | J25: 88 | K25: 2854762 | L25: 3.533 | M25: 13.515 | N25: 27.748 | O25: 13465.86 | U25: Valid
A26: Together | B26: not disclosed | C26: Qwen3.5-27B | D26: 1k | E26: r16/a32/all-linear | F26: 8 | G26: 2 | H26: not disclosed | J26: 21 | K26: 287860 | L26: 6.333 | M26: 6.104 | N26: 23.871 | O26: 757.53 | U26: Caution | V26: Train time looks distorted by a fixed per-job overhead; grad accumulation=4 auto-applied to reach effective batch 8
A27: Together | B27: not disclosed | C27: Qwen3.5-27B | D27: 5k | E27: r16/a32/all-linear | F27: 8 | G27: 2 | H27: not disclosed | J27: 44 | K27: 1435064 | L27: 7.167 | M27: 5.487 | N27: 40.97 | O27: 3337.36 | U27: Valid | V27: Grad accumulation=4 auto-applied to reach effective batch 8
A28: Together | B28: not disclosed | C28: Qwen3.5-27B | D28: 10k | E28: r16/a32/all-linear | F28: 8 | G28: 2 | H28: not disclosed | J28: 88 | K28: 2854762 | L28: 10.933 | M28: 16.151 | N28: 41.434 | O28: 4351.77 | U28: Valid | V28: Grad accumulation=4 auto-applied to reach effective batch 8
A29: A100 | B29: NVIDIA A100-SXM4-80GB | C29: gpt-oss-20B | D29: 1k | E29: r16/a32/all-linear | F29: 8 | G29: 1 | H29: TRUE | I29: 7962624 | J29: 10 | K29: 327680 | L29: 4.6316366 | N29: 6.9519405 | O29: 1179.1368 | P29: 1181.816 | Q29: 52.477411 | R29: 2.0391489 | S29: 0.99685741 | U29: Valid | V29: Gradient checkpointing forced (micro_batch=1): MoE routing activates different experts per batch, so memory use varies by input; automatic batch-size detection was unreliable for this model.
A30: A100 | B30: NVIDIA A100-SXM4-80GB | C30: gpt-oss-20B | D30: 5k | E30: r16/a32/all-linear | F30: 8 | G30: 1 | H30: TRUE | I30: 7962624 | J30: 51 | K30: 1671168 | L30: 23.589961 | N30: 25.87966 | O30: 1180.7056 | P30: 1182.9101 | Q30: 52.477411 | R30: 2.0391489 | S30: 0.81416301 | U30: Valid | V30: Gradient checkpointing forced (micro_batch=1): MoE routing activates different experts per batch, so memory use varies by input; automatic batch-size detection was unreliable for this model.
A31: A100 | B31: NVIDIA A100-SXM4-80GB | C31: gpt-oss-20B | D31: 10k | E31: r16/a32/all-linear | F31: 8 | G31: 1 | H31: TRUE | I31: 7962624 | J31: 101 | K31: 3309568 | L31: 46.719343 | N31: 48.979654 | O31: 1180.6559 | P31: 1182.5142 | Q31: 52.477411 | R31: 2.0391489 | S31: 0.83494211 | U31: Valid | V31: Gradient checkpointing forced (micro_batch=1): MoE routing activates different experts per batch, so memory use varies by input; automatic batch-size detection was unreliable for this model.
A32: H100 | B32: NVIDIA H100 PCIe | C32: gpt-oss-20B | D32: 1k | E32: r16/a32/all-linear | F32: 8 | G32: 1 | H32: TRUE | I32: 7962624 | J32: 10 | K32: 327680 | L32: 3.8901418 | N32: 4.7794353 | O32: 1403.8906 | P32: 1371.6835 | Q32: 52.527481 | R32: 2.037081 | S32: 0.99681152 | U32: Valid | V32: Gradient checkpointing forced (micro_batch=1): MoE routing activates different experts per batch, so memory use varies by input; automatic batch-size detection was unreliable for this model.
A33: H100 | B33: NVIDIA H100 PCIe | C33: gpt-oss-20B | D33: 5k | E33: r16/a32/all-linear | F33: 8 | G33: 1 | H33: TRUE | I33: 7962624 | J33: 51 | K33: 1671168 | L33: 20.406113 | N33: 21.301929 | O33: 1364.9244 | P33: 1360.4608 | Q33: 52.527481 | R33: 2.037081 | S33: 0.81348246 | U33: Valid | V33: Gradient checkpointing forced (micro_batch=1): MoE routing activates different experts per batch, so memory use varies by input; automatic batch-size detection was unreliable for this model.
A34: H100 | B34: NVIDIA H100 PCIe | C34: gpt-oss-20B | D34: 10k | E34: r16/a32/all-linear | F34: 8 | G34: 1 | H34: TRUE | I34: 7962624 | J34: 101 | K34: 3309568 | L34: 40.438762 | N34: 41.34275 | O34: 1364.0246 | P34: 1360.3321 | Q34: 52.527481 | R34: 2.037081 | S34: 0.83733702 | U34: Valid | V34: Gradient checkpointing forced (micro_batch=1): MoE routing activates different experts per batch, so memory use varies by input; automatic batch-size detection was unreliable for this model.
A35: Together | B35: not disclosed | C35: gpt-oss-20B | D35: 1k | F35: 8 | H35: not disclosed | U35: Pending | V35: Job not submitted: Together account balance/credit limit insufficient (error 402, requires >= $4.00 combined balance+credit). Needs a credit top-up before this can be run.
A36: Together | B36: not disclosed | C36: gpt-oss-20B | D36: 5k | E36: r16/a32/k_proj,o_proj,q_proj,v_proj | F36: 8 | G36: 1 | H36: not disclosed | J36: 52 | K36: 1672237 | L36: 4.9333333 | M36: 3.4766667 | N36: 10.826667 | O36: 5649.4493 | U36: Valid | V36: Together silently used its default LoRA target modules (k_proj/o_proj/q_proj/v_proj) instead of the requested all-linear.
A37: Together | B37: not disclosed | C37: gpt-oss-20B | D37: 10k | F37: 8 | H37: not disclosed | U37: Pending | V37: Job not submitted: Together account balance/credit limit insufficient (error 402, requires >= $4.00 combined balance+credit). Needs a credit top-up before this can be run.

Sheet Config
A1: key | B1: value | C1: notes
A2: hours_per_month | B2: 730 | C2: Global hourly conversion
A3: a100_monthly_usd | B3: 10000 | C3: For 8x A100 basis
A4: a100_gpus | B4: 8 | C4: A100 count
A5: h100_monthly_usd | B5: 1400 | C5: Single H100 monthly
A6: utilisation_U | B6: 1 | C6: Serving utilization divisor
A7: latency_target_s | B7: 2 | C7: Iso-latency p99 threshold

Sheet Normalised costs
A1: verification | B1: job_id | C1: model | D1: dataset_size | E1: tokens | F1: billed_usd | G1: together_list_rate_usd_per_million | H1: together_min_charge_usd | I1: min_charge_binding | J1: together_effective_usd_per_million | K1: odyn_a100_steady_tokens_per_s | L1: odyn_h100_steady_tokens_per_s | M1: wall_min | N1: odyn_a100_steady_formula_usd_per_million | O1: odyn_h100_steady_formula_usd_per_million | P1: odyn_a100_effective_formula_usd_per_million | Q1: odyn_h100_effective_formula_usd_per_million | R1: together_effective_formula_usd_per_million
A2: CLI_VERIFIED | B2: ft-f7900121-8871 | C2: openai/gpt-oss-20b | D2: 10k | E2: 3329128 | F2: 4 | G2: 0.4 | H2: 4 | I2: TRUE | J2: 1.202 | K2: 1182.5142 | L2: 1360.3321 | M2: 14.559 | N2: =IF(K2>0,ROUND((Config!$B$3/Config!$B$4/Config!$B$2)/(K2*3600)*1000000,3),"UNAVAILABLE") | O2: =IF(L2>0,ROUND((Config!$B$5/Config!$B$2)/(L2*3600)*1000000,3),"UNAVAILABLE") | P2: =IF(AND(E2>0,M2>0),ROUND((Config!$B$3/Config!$B$4/Config!$B$2)*(M2/60)/(E2/1000000),3),"UNAVAILABLE") | Q2: =IF(AND(E2>0,M2>0),ROUND((Config!$B$5/Config!$B$2)*(M2/60)/(E2/1000000),3),"UNAVAILABLE") | R2: =IF(E2>0,ROUND(F2/(E2/1000000),3),"UNAVAILABLE")
A3: CLI_VERIFIED | B3: ft-13dd5f5f-d688 | C3: openai/gpt-oss-20b | D3: 1k | E3: 335328 | F3: 4 | G3: 0.4 | H3: 4 | I3: TRUE | J3: 11.929 | K3: 1181.816 | L3: 1371.6835 | M3: 9.359 | N3: =IF(K3>0,ROUND((Config!$B$3/Config!$B$4/Config!$B$2)/(K3*3600)*1000000,3),"UNAVAILABLE") | O3: =IF(L3>0,ROUND((Config!$B$5/Config!$B$2)/(L3*3600)*1000000,3),"UNAVAILABLE") | P3: =IF(AND(E3>0,M3>0),ROUND((Config!$B$3/Config!$B$4/Config!$B$2)*(M3/60)/(E3/1000000),3),"UNAVAILABLE") | Q3: =IF(AND(E3>0,M3>0),ROUND((Config!$B$5/Config!$B$2)*(M3/60)/(E3/1000000),3),"UNAVAILABLE") | R3: =IF(E3>0,ROUND(F3/(E3/1000000),3),"UNAVAILABLE")
A4: CLI_VERIFIED | B4: ft-15dec247-d184 | C4: openai/gpt-oss-20b | D4: 10k | E4: 3329128 | F4: 4 | G4: 0.4 | H4: 4 | I4: TRUE | J4: 1.202 | K4: 1182.5142 | L4: 1360.3321 | M4: 14.213 | N4: =IF(K4>0,ROUND((Config!$B$3/Config!$B$4/Config!$B$2)/(K4*3600)*1000000,3),"UNAVAILABLE") | O4: =IF(L4>0,ROUND((Config!$B$5/Config!$B$2)/(L4*3600)*1000000,3),"UNAVAILABLE") | P4: =IF(AND(E4>0,M4>0),ROUND((Config!$B$3/Config!$B$4/Config!$B$2)*(M4/60)/(E4/1000000),3),"UNAVAILABLE") | Q4: =IF(AND(E4>0,M4>0),ROUND((Config!$B$5/Config!$B$2)*(M4/60)/(E4/1000000),3),"UNAVAILABLE") | R4: =IF(E4>0,ROUND(F4/(E4/1000000),3),"UNAVAILABLE")
A5: CLI_VERIFIED | B5: ft-800f78cc-228c | C5: openai/gpt-oss-20b | D5: 1k | E5: 335328 | F5: 4 | G5: 0.4 | H5: 4 | I5: TRUE | J5: 11.929 | K5: 1181.816 | L5: 1371.6835 | M5: 8.68 | N5: =IF(K5>0,ROUND((Config!$B$3/Config!$B$4/Config!$B$2)/(K5*3600)*1000000,3),"UNAVAILABLE") | O5: =IF(L5>0,ROUND((Config!$B$5/Config!$B$2)/(L5*3600)*1000000,3),"UNAVAILABLE") | P5: =IF(AND(E5>0,M5>0),ROUND((Config!$B$3/Config!$B$4/Config!$B$2)*(M5/60)/(E5/1000000),3),"UNAVAILABLE") | Q5: =IF(AND(E5>0,M5>0),ROUND((Config!$B$5/Config!$B$2)*(M5/60)/(E5/1000000),3),"UNAVAILABLE") | R5: =IF(E5>0,ROUND(F5/(E5/1000000),3),"UNAVAILABLE")
A6: CLI_VERIFIED | B6: ft-db904a53-822c | C6: openai/gpt-oss-20b | D6: 10k | E6: 3329128 | F6: 4 | G6: 0.4 | H6: 4 | I6: TRUE | J6: 1.202 | K6: 1182.5142 | L6: 1360.3321 | M6: 14.632 | N6: =IF(K6>0,ROUND((Config!$B$3/Config!$B$4/Config!$B$2)/(K6*3600)*1000000,3),"UNAVAILABLE") | O6: =IF(L6>0,ROUND((Config!$B$5/Config!$B$2)/(L6*3600)*1000000,3),"UNAVAILABLE") | P6: =IF(AND(E6>0,M6>0),ROUND((Config!$B$3/Config!$B$4/Config!$B$2)*(M6/60)/(E6/1000000),3),"UNAVAILABLE") | Q6: =IF(AND(E6>0,M6>0),ROUND((Config!$B$5/Config!$B$2)*(M6/60)/(E6/1000000),3),"UNAVAILABLE") | R6: =IF(E6>0,ROUND(F6/(E6/1000000),3),"UNAVAILABLE")
A7: CLI_VERIFIED | B7: ft-d3580354-5bff | C7: openai/gpt-oss-20b | D7: 1k | E7: 335328 | F7: 4 | G7: 0.4 | H7: 4 | I7: TRUE | J7: 11.929 | K7: 1181.816 | L7: 1371.6835 | M7: 8.389 | N7: =IF(K7>0,ROUND((Config!$B$3/Config!$B$4/Config!$B$2)/(K7*3600)*1000000,3),"UNAVAILABLE") | O7: =IF(L7>0,ROUND((Config!$B$5/Config!$B$2)/(L7*3600)*1000000,3),"UNAVAILABLE") | P7: =IF(AND(E7>0,M7>0),ROUND((Config!$B$3/Config!$B$4/Config!$B$2)*(M7/60)/(E7/1000000),3),"UNAVAILABLE") | Q7: =IF(AND(E7>0,M7>0),ROUND((Config!$B$5/Config!$B$2)*(M7/60)/(E7/1000000),3),"UNAVAILABLE") | R7: =IF(E7>0,ROUND(F7/(E7/1000000),3),"UNAVAILABLE")
A8: CLI_VERIFIED | B8: ft-2fe19cba-b1d3 | C8: openai/gpt-oss-20b | D8: 10k | E8: 3329128 | F8: 4 | G8: 0.4 | H8: 4 | I8: TRUE | J8: 1.202 | K8: 1182.5142 | L8: 1360.3321 | M8: 14.485 | N8: =IF(K8>0,ROUND((Config!$B$3/Config!$B$4/Config!$B$2)/(K8*3600)*1000000,3),"UNAVAILABLE") | O8: =IF(L8>0,ROUND((Config!$B$5/Config!$B$2)/(L8*3600)*1000000,3),"UNAVAILABLE") | P8: =IF(AND(E8>0,M8>0),ROUND((Config!$B$3/Config!$B$4/Config!$B$2)*(M8/60)/(E8/1000000),3),"UNAVAILABLE") | Q8: =IF(AND(E8>0,M8>0),ROUND((Config!$B$5/Config!$B$2)*(M8/60)/(E8/1000000),3),"UNAVAILABLE") | R8: =IF(E8>0,ROUND(F8/(E8/1000000),3),"UNAVAILABLE")
A9: CLI_VERIFIED | B9: ft-1fce124e-17b1 | C9: openai/gpt-oss-20b | D9: 1k | E9: 335328 | F9: 4 | G9: 0.4 | H9: 4 | I9: TRUE | J9: 11.929 | K9: 1181.816 | L9: 1371.6835 | M9: 9.06 | N9: =IF(K9>0,ROUND((Config!$B$3/Config!$B$4/Config!$B$2)/(K9*3600)*1000000,3),"UNAVAILABLE") | O9: =IF(L9>0,ROUND((Config!$B$5/Config!$B$2)/(L9*3600)*1000000,3),"UNAVAILABLE") | P9: =IF(AND(E9>0,M9>0),ROUND((Config!$B$3/Config!$B$4/Config!$B$2)*(M9/60)/(E9/1000000),3),"UNAVAILABLE") | Q9: =IF(AND(E9>0,M9>0),ROUND((Config!$B$5/Config!$B$2)*(M9/60)/(E9/1000000),3),"UNAVAILABLE") | R9: =IF(E9>0,ROUND(F9/(E9/1000000),3),"UNAVAILABLE")
A10: CLI_VERIFIED | B10: ft-c605677b-1ee3 | C10: openai/gpt-oss-20b | D10: 5k | E10: 1672237 | F10: 4 | G10: 0.4 | H10: 4 | I10: TRUE | J10: 2.392 | K10: 1182.9101 | L10: 1360.4608 | M10: 10.834 | N10: =IF(K10>0,ROUND((Config!$B$3/Config!$B$4/Config!$B$2)/(K10*3600)*1000000,3),"UNAVAILABLE") | O10: =IF(L10>0,ROUND((Config!$B$5/Config!$B$2)/(L10*3600)*1000000,3),"UNAVAILABLE") | P10: =IF(AND(E10>0,M10>0),ROUND((Config!$B$3/Config!$B$4/Config!$B$2)*(M10/60)/(E10/1000000),3),"UNAVAILABLE") | Q10: =IF(AND(E10>0,M10>0),ROUND((Config!$B$5/Config!$B$2)*(M10/60)/(E10/1000000),3),"UNAVAILABLE") | R10: =IF(E10>0,ROUND(F10/(E10/1000000),3),"UNAVAILABLE")
A11: CLI_VERIFIED | B11: ft-79f6d24e-ff70 | C11: openai/gpt-oss-20b | D11: 10k | E11: 3329128 | F11: 4 | G11: 0.4 | H11: 4 | I11: TRUE | J11: 1.202 | K11: 1182.5142 | L11: 1360.3321 | M11: 14.382 | N11: =IF(K11>0,ROUND((Config!$B$3/Config!$B$4/Config!$B$2)/(K11*3600)*1000000,3),"UNAVAILABLE") | O11: =IF(L11>0,ROUND((Config!$B$5/Config!$B$2)/(L11*3600)*1000000,3),"UNAVAILABLE") | P11: =IF(AND(E11>0,M11>0),ROUND((Config!$B$3/Config!$B$4/Config!$B$2)*(M11/60)/(E11/1000000),3),"UNAVAILABLE") | Q11: =IF(AND(E11>0,M11>0),ROUND((Config!$B$5/Config!$B$2)*(M11/60)/(E11/1000000),3),"UNAVAILABLE") | R11: =IF(E11>0,ROUND(F11/(E11/1000000),3),"UNAVAILABLE")
A12: CLI_VERIFIED | B12: ft-c8bfe61e-9d76 | C12: openai/gpt-oss-20b | D12: 1k | E12: 335328 | F12: 4 | G12: 0.4 | H12: 4 | I12: TRUE | J12: 11.929 | K12: 1181.816 | L12: 1371.6835 | M12: 8.67 | N12: =IF(K12>0,ROUND((Config!$B$3/Config!$B$4/Config!$B$2)/(K12*3600)*1000000,3),"UNAVAILABLE") | O12: =IF(L12>0,ROUND((Config!$B$5/Config!$B$2)/(L12*3600)*1000000,3),"UNAVAILABLE") | P12: =IF(AND(E12>0,M12>0),ROUND((Config!$B$3/Config!$B$4/Config!$B$2)*(M12/60)/(E12/1000000),3),"UNAVAILABLE") | Q12: =IF(AND(E12>0,M12>0),ROUND((Config!$B$5/Config!$B$2)*(M12/60)/(E12/1000000),3),"UNAVAILABLE") | R12: =IF(E12>0,ROUND(F12/(E12/1000000),3),"UNAVAILABLE")
A13: CLI_VERIFIED | B13: ft-203f3d09-1cf6 | C13: openai/gpt-oss-20b | D13: 5k | E13: 1672237 | F13: 4 | G13: 0.4 | H13: 4 | I13: TRUE | J13: 2.392 | K13: 1182.9101 | L13: 1360.4608 | M13: 11.805 | N13: =IF(K13>0,ROUND((Config!$B$3/Config!$B$4/Config!$B$2)/(K13*3600)*1000000,3),"UNAVAILABLE") | O13: =IF(L13>0,ROUND((Config!$B$5/Config!$B$2)/(L13*3600)*1000000,3),"UNAVAILABLE") | P13: =IF(AND(E13>0,M13>0),ROUND((Config!$B$3/Config!$B$4/Config!$B$2)*(M13/60)/(E13/1000000),3),"UNAVAILABLE") | Q13: =IF(AND(E13>0,M13>0),ROUND((Config!$B$5/Config!$B$2)*(M13/60)/(E13/1000000),3),"UNAVAILABLE") | R13: =IF(E13>0,ROUND(F13/(E13/1000000),3),"UNAVAILABLE")
... A17: CLI_VERIFIED | B17: ft-bcf4ff51-89fc | C17: Qwen/Qwen3.5-9B | D17: 5k | E17: 1435064 | F17: 4 | G17: 0.34 | H17: 4 | I17: TRUE | J17: 2.787 | K17: 3210.72 | L17: 3603.26 | M17: 47.444 | N17: =IF(K17>0,ROUND((Config!$B$3/Config!$B$4/Config!$B$2)/(K17*3600)*1000000,3),"UNAVAILABLE") | O17: =IF(L17>0,ROUND((Config!$B$5/Config!$B$2)/(L17*3600)*1000000,3),"UNAVAILABLE") | P17: =IF(AND(E17>0,M17>0),ROUND((Config!$B$3/Config!$B$4/Config!$B$2)*(M17/60)/(E17/1000000),3),"UNAVAILABLE") | Q17: =IF(AND(E17>0,M17>0),ROUND((Config!$B$5/Config!$B$2)*(M17/60)/(E17/1000000),3),"UNAVAILABLE") | R17: =IF(E17>0,ROUND(F17/(E17/1000000),3),"UNAVAILABLE")
A18: WORKBOOK_UNVERIFIED | B18: UNAVAILABLE | C18: Qwen3.5-4B | D18: 1k | E18: 287860 | G18: 0.34 | H18: 4 | I18: TRUE | K18: 4458.27 | L18: 5804.29 | M18: 16.051 | N18: =IF(K18>0,ROUND((Config!$B$3/Config!$B$4/Config!$B$2)/(K18*3600)*1000000,3),"UNAVAILABLE") | O18: =IF(L18>0,ROUND((Config!$B$5/Config!$B$2)/(L18*3600)*1000000,3),"UNAVAILABLE") | P18: =IF(AND(E18>0,M18>0),ROUND((Config!$B$3/Config!$B$4/Config!$B$2)*(M18/60)/(E18/1000000),3),"UNAVAILABLE") | Q18: =IF(AND(E18>0,M18>0),ROUND((Config!$B$5/Config!$B$2)*(M18/60)/(E18/1000000),3),"UNAVAILABLE") | R18: =IF(E18>0,ROUND(F18/(E18/1000000),3),"UNAVAILABLE")
A19: WORKBOOK_UNVERIFIED | B19: UNAVAILABLE | C19: Qwen3.5-4B | D19: 10k | E19: 2854762 | G19: 0.34 | H19: 4 | I19: TRUE | K19: 4455.63 | L19: 5121.91 | M19: 19.259 | N19: =IF(K19>0,ROUND((Config!$B$3/Config!$B$4/Config!$B$2)/(K19*3600)*1000000,3),"UNAVAILABLE") | O19: =IF(L19>0,ROUND((Config!$B$5/Config!$B$2)/(L19*3600)*1000000,3),"UNAVAILABLE") | P19: =IF(AND(E19>0,M19>0),ROUND((Config!$B$3/Config!$B$4/Config!$B$2)*(M19/60)/(E19/1000000),3),"UNAVAILABLE") | Q19: =IF(AND(E19>0,M19>0),ROUND((Config!$B$5/Config!$B$2)*(M19/60)/(E19/1000000),3),"UNAVAILABLE") | R19: =IF(E19>0,ROUND(F19/(E19/1000000),3),"UNAVAILABLE")
A20: WORKBOOK_UNVERIFIED | B20: UNAVAILABLE | C20: Qwen3.5-9B | D20: 1k | E20: 287860 | G20: 0.34 | H20: 4 | I20: TRUE | K20: 3214.78 | L20: 3739.78 | M20: 18.466 | N20: =IF(K20>0,ROUND((Config!$B$3/Config!$B$4/Config!$B$2)/(K20*3600)*1000000,3),"UNAVAILABLE") | O20: =IF(L20>0,ROUND((Config!$B$5/Config!$B$2)/(L20*3600)*1000000,3),"UNAVAILABLE") | P20: =IF(AND(E20>0,M20>0),ROUND((Config!$B$3/Config!$B$4/Config!$B$2)*(M20/60)/(E20/1000000),3),"UNAVAILABLE") | Q20: =IF(AND(E20>0,M20>0),ROUND((Config!$B$5/Config!$B$2)*(M20/60)/(E20/1000000),3),"UNAVAILABLE") | R20: =IF(E20>0,ROUND(F20/(E20/1000000),3),"UNAVAILABLE")
A21: WORKBOOK_UNVERIFIED | B21: UNAVAILABLE | C21: Qwen3.5-9B | D21: 10k | E21: 2854762 | G21: 0.34 | H21: 4 | I21: TRUE | K21: 3213.38 | L21: 3603.12 | M21: 27.748 | N21: =IF(K21>0,ROUND((Config!$B$3/Config!$B$4/Config!$B$2)/(K21*3600)*1000000,3),"UNAVAILABLE") | O21: =IF(L21>0,ROUND((Config!$B$5/Config!$B$2)/(L21*3600)*1000000,3),"UNAVAILABLE") | P21: =IF(AND(E21>0,M21>0),ROUND((Config!$B$3/Config!$B$4/Config!$B$2)*(M21/60)/(E21/1000000),3),"UNAVAILABLE") | Q21: =IF(AND(E21>0,M21>0),ROUND((Config!$B$5/Config!$B$2)*(M21/60)/(E21/1000000),3),"UNAVAILABLE") | R21: =IF(E21>0,ROUND(F21/(E21/1000000),3),"UNAVAILABLE")
A22: WORKBOOK_UNVERIFIED | B22: UNAVAILABLE | C22: Qwen3.5-27B | D22: 1k | E22: 287860 | G22: 1.05 | H22: 4 | I22: TRUE | K22: 809.44 | L22: 875.06 | M22: 23.871 | N22: =IF(K22>0,ROUND((Config!$B$3/Config!$B$4/Config!$B$2)/(K22*3600)*1000000,3),"UNAVAILABLE") | O22: =IF(L22>0,ROUND((Config!$B$5/Config!$B$2)/(L22*3600)*1000000,3),"UNAVAILABLE") | P22: =IF(AND(E22>0,M22>0),ROUND((Config!$B$3/Config!$B$4/Config!$B$2)*(M22/60)/(E22/1000000),3),"UNAVAILABLE") | Q22: =IF(AND(E22>0,M22>0),ROUND((Config!$B$5/Config!$B$2)*(M22/60)/(E22/1000000),3),"UNAVAILABLE") | R22: =IF(E22>0,ROUND(F22/(E22/1000000),3),"UNAVAILABLE")
A23: WORKBOOK_UNVERIFIED | B23: UNAVAILABLE | C23: Qwen3.5-27B | D23: 10k | E23: 2854762 | G23: 1.05 | H23: 4 | I23: TRUE | K23: 809.74 | L23: 872.39 | M23: 41.434 | N23: =IF(K23>0,ROUND((Config!$B$3/Config!$B$4/Config!$B$2)/(K23*3600)*1000000,3),"UNAVAILABLE") | O23: =IF(L23>0,ROUND((Config!$B$5/Config!$B$2)/(L23*3600)*1000000,3),"UNAVAILABLE") | P23: =IF(AND(E23>0,M23>0),ROUND((Config!$B$3/Config!$B$4/Config!$B$2)*(M23/60)/(E23/1000000),3),"UNAVAILABLE") | Q23: =IF(AND(E23>0,M23>0),ROUND((Config!$B$5/Config!$B$2)*(M23/60)/(E23/1000000),3),"UNAVAILABLE") | R23: =IF(E23>0,ROUND(F23/(E23/1000000),3),"UNAVAILABLE")

Sheet Normalised serving
A1: model | B1: concurrency | C1: a100_tps | D1: h100_tps | E1: together_tps | F1: together_rate_source | G1: a100_formula_usd_per_m_output | H1: h100_formula_usd_per_m_output | I1: together_formula_usd_per_m_output
A2: 4B | B2: 16 | C2: 1506.809 | D2: 1702.394 | E2: 1533.4 | F2: ASSUMED_1xH100 | G2: =IF(C2>0,ROUND(((Config!$B$3/Config!$B$4/Config!$B$2)/(C2*3600)*1000000)/Config!$B$6,3),"UNAVAILABLE") | H2: =IF(D2>0,ROUND(((Config!$B$5/Config!$B$2)/(D2*3600)*1000000)/Config!$B$6,3),"UNAVAILABLE") | I2: =IF(E2>0,ROUND((5.49/(E2*3600)*1000000)/Config!$B$6,3),"UNAVAILABLE")
A3: 9B | B3: 16 | C3: 1137.232 | D3: 1170.604 | E3: 1104.579 | F3: ASSUMED_1xH100 | G3: =IF(C3>0,ROUND(((Config!$B$3/Config!$B$4/Config!$B$2)/(C3*3600)*1000000)/Config!$B$6,3),"UNAVAILABLE") | H3: =IF(D3>0,ROUND(((Config!$B$5/Config!$B$2)/(D3*3600)*1000000)/Config!$B$6,3),"UNAVAILABLE") | I3: =IF(E3>0,ROUND((5.49/(E3*3600)*1000000)/Config!$B$6,3),"UNAVAILABLE")
A4: 27B | B4: 16 | C4: 378.058 | D4: 416.549 | E4: 596.4 | F4: ASSUMED_1xH100 | G4: =IF(C4>0,ROUND(((Config!$B$3/Config!$B$4/Config!$B$2)/(C4*3600)*1000000)/Config!$B$6,3),"UNAVAILABLE") | H4: =IF(D4>0,ROUND(((Config!$B$5/Config!$B$2)/(D4*3600)*1000000)/Config!$B$6,3),"UNAVAILABLE") | I4: =IF(E4>0,ROUND((5.49/(E4*3600)*1000000)/Config!$B$6,3),"UNAVAILABLE")
A5: 27B | B5: 32 | C5: 628.29 | D5: 725.432 | E5: 920.806 | F5: ASSUMED_1xH100 | G5: =IF(C5>0,ROUND(((Config!$B$3/Config!$B$4/Config!$B$2)/(C5*3600)*1000000)/Config!$B$6,3),"UNAVAILABLE") | H5: =IF(D5>0,ROUND(((Config!$B$5/Config!$B$2)/(D5*3600)*1000000)/Config!$B$6,3),"UNAVAILABLE") | I5: =IF(E5>0,ROUND((5.49/(E5*3600)*1000000)/Config!$B$6,3),"UNAVAILABLE")
A6: 27B | B6: 64 | C6: 955.492 | D6: 1131.698 | E6: 1369.677 | F6: ASSUMED_1xH100 | G6: =IF(C6>0,ROUND(((Config!$B$3/Config!$B$4/Config!$B$2)/(C6*3600)*1000000)/Config!$B$6,3),"UNAVAILABLE") | H6: =IF(D6>0,ROUND(((Config!$B$5/Config!$B$2)/(D6*3600)*1000000)/Config!$B$6,3),"UNAVAILABLE") | I6: =IF(E6>0,ROUND((5.49/(E6*3600)*1000000)/Config!$B$6,3),"UNAVAILABLE")
A7: gpt-oss-20B | B7: 16 | C7: 1747.186 | D7: 1716.174 | E7: 1492.888 | F7: ASSUMED_1xH100 | G7: =IF(C7>0,ROUND(((Config!$B$3/Config!$B$4/Config!$B$2)/(C7*3600)*1000000)/Config!$B$6,3),"UNAVAILABLE") | H7: =IF(D7>0,ROUND(((Config!$B$5/Config!$B$2)/(D7*3600)*1000000)/Config!$B$6,3),"UNAVAILABLE") | I7: =IF(E7>0,ROUND((5.49/(E7*3600)*1000000)/Config!$B$6,3),"UNAVAILABLE")
